<mujoco model="trifinger_with_ground">

    <visual>
        <global offwidth="1280" offheight="960"/>
    </visual>

    <compiler angle="radian" meshdir="assets"/>

    <option cone="elliptic" impratio="10.0" integrator="Euler"
          iterations="20" ls_iterations="10" solver='Newton' tolerance="0" noslip_iterations="0">

        <flag   eulerdamp="enable"
                clampctrl="disable"
                warmstart="enable"
                frictionloss="enable"
                fwdinv="enable"
                midphase="enable"
                multiccd="disable"   
                invdiscrete="disable">
        </flag>
    </option>

    <size njmax="500" nconmax="100"/>

    <asset>
        <mesh name="SIM__BL_Finger_Base" file="SIM__BL-Finger_Base.stl"/>
        <mesh name="SIM__BL_Finger_Proximal" file="SIM__BL-Finger_Proximal.stl"/>
        <mesh name="SIM__BL_Finger_Intermediate" file="SIM__BL-Finger_Intermediate.stl"/>
        <mesh name="SIM__BL_FINGER_TIP_LINK" file="SIM_BL_FINGER_TIP_LINK.stl"/>

        <texture type="2d" name="groundplane" builtin="checker" mark="edge" rgb1="0.2 0.3 0.4"
                 rgb2="0.1 0.2 0.3" markrgb="0.8 0.8 0.8" width="300" height="300"/>
        <material name="groundplane" texture="groundplane" texuniform="true" texrepeat="5 5"
                  reflectance="0.0"/>

        <!-- Define materials for the cube -->
        <material name="cube_material" rgba="0.0 0.0 1.0 1.0"/> <!-- Blue cube -->
    </asset>

    <visual>
        <rgba haze="0.15 0.25 0.35 1"/>
        <quality shadowsize="8192"/>
        <global azimuth="130" elevation="-40"/>
    </visual>

    <!-- Collision Options -->
    <option>
        <!-- No special options needed since we're using contype and conaffinity -->
    </option>

 <worldbody>

        <!-- Light and camera -->
        <light directional="true" ambient="0.2 0.2 0.2"
               diffuse="0.8 0.8 0.8" castshadow="false"
               pos="0 1 4" dir="0 0 -1" name="light0"/>
        <camera name="demo-cam" pos="-0.005 -0.529 0.575"
                xyaxes="1.000 -0.002 -0.000 0.001 0.644 0.765"/>

        <!-- Table geom: collisions on (contype=1, conaffinity=1) -->
        <geom name="table" rgba="0.8 0.8 0.8 1.0" friction="0.8"
              size="0 0 0.05" type="plane" material="groundplane"
              condim="6"
              contype="1" conaffinity="1"/>

        <!-- ================== Trifinger Base (shells) ================== -->
        <!-- contype=1, conaffinity=2 => collides with table, but not with each other -->
        <geom pos="0 0.219 0.29" type="mesh"
              mesh="SIM__BL_Finger_Base"
              rgba="0.5 0 0 1"
              contype="1" conaffinity="2"/>

        <geom pos="0.18966 -0.1095 0.29" quat="0.5 0 0 -0.866025"
              type="mesh" mesh="SIM__BL_Finger_Base"
              rgba="0 0.5 0 1"
              contype="1" conaffinity="2"/>

        <geom pos="-0.18966 -0.1095 0.29" quat="-0.5 0 0 -0.866025"
              type="mesh" mesh="SIM__BL_Finger_Base"
              rgba="0 0.5 0.5 1"
              contype="1" conaffinity="2"/>


        <!-- ================== ARM 1 (0 deg) ================== -->
        <body name="finger_upper_link_0" pos="0 0.04 0.29">
            <inertial pos="0 0.06 0" quat="0.707107 0.707107 0 0"
                      mass="0.2" diaginertia="0.000353333 0.000353333 5.33333e-05"/>
            <joint name="finger_base_to_upper_joint_0" pos="0 0 0"
                   axis="0 1 0" limited="true" range="-1.5708 1.5708"/>

            <!-- Proximal link geometry -->
            <geom pos="0 -0.02695 0" type="mesh"
                  mesh="SIM__BL_Finger_Proximal"
                  rgba="0.5 0 0 1"
                  contype="1" conaffinity="2"/>

            <body name="finger_middle_link_0" pos="0 0 0">
                <inertial pos="0.028 0 -0.08" mass="0.2"
                          diaginertia="0.000353333 0.000353333 5.33333e-05"/>
                <joint name="finger_upper_to_middle_joint_0" pos="0 0 0"
                       axis="-1 0 0" limited="true"
                       range="-1.35263 4.49422"/>
                <!-- Intermediate link geometry -->
                <geom pos="0.014 0 0" quat="0.707107 0.707107 0 0"
                      type="mesh" mesh="SIM__BL_Finger_Intermediate"
                      rgba="0.5 0 0 1"
                      contype="1" conaffinity="2"/>

                <body name="finger_lower_link_0" pos="0 0 -0.16">
                    <inertial pos="0 0 -0.126667" mass="0.03"
                              diaginertia="8.36667e-05 8.36667e-05 1e-06"/>
                    <joint name="finger_middle_to_lower_joint_0" pos="0 0 0"
                           axis="1 0 0" limited="true"
                           range="-3.00197 3.00197"/>
                    <!-- Tip link geometry -->
                    <geom name="finger_tip_0"
                          friction="0.9 0.005 0.0001"
                          pos="0.014 0 0" quat="0.707107 0.707107 0 0"
                          type="mesh" mesh="SIM__BL_FINGER_TIP_LINK"
                          rgba="0.5 0 0 1"
                          contype="1" conaffinity="2"/>
                    <site rgba="0.5 0.0 0.0 1" size="0.001" pos="0 0 -0.16" name="finger_tip_0_site"/>
                </body>
            </body>
        </body>

        <!-- ================== ARM 2 (120 deg) ================== -->
        <body name="finger_upper_link_120" pos="0.034641 -0.02 0.29"
              quat="0.5 0 0 -0.866025">
            <inertial pos="0 0.06 0" quat="0.707107 0.707107 0 0"
                      mass="0.2" diaginertia="0.000353333 0.000353333 5.33333e-05"/>
            <joint name="finger_base_to_upper_joint_120" pos="0 0 0"
                   axis="0 1 0" limited="true" range="-1.5708 1.5708"/>

            <geom pos="0 -0.02695 0" type="mesh"
                  mesh="SIM__BL_Finger_Proximal"
                  rgba="0 0.5 0 1"
                  contype="1" conaffinity="2"/>

            <body name="finger_middle_link_120" pos="0 0 0">
                <inertial pos="0.028 0 -0.08" mass="0.2"
                          diaginertia="0.000353333 0.000353333 5.33333e-05"/>
                <joint name="finger_upper_to_middle_joint_120" pos="0 0 0"
                       axis="-1 0 0" limited="true"
                       range="-1.35263 4.49422"/>
                <geom pos="0.014 0 0" quat="0.707107 0.707107 0 0"
                      type="mesh" mesh="SIM__BL_Finger_Intermediate"
                      rgba="0 0.5 0 1"
                      contype="1" conaffinity="2"/>

                <body name="finger_lower_link_120" pos="0 0 -0.16">
                    <inertial pos="0 0 -0.126667" mass="0.03"
                              diaginertia="8.36667e-05 8.36667e-05 1e-06"/>
                    <joint name="finger_middle_to_lower_joint_120" pos="0 0 0"
                           axis="1 0 0" limited="true"
                           range="-3.00197 3.00197"/>
                    <geom name="finger_tip_120"
                          friction="0.9 0.005 0.0001"
                          pos="0.014 0 0" quat="0.707107 0.707107 0 0"
                          type="mesh" mesh="SIM__BL_FINGER_TIP_LINK"
                          rgba="0 0.5 0 1"
                          contype="1" conaffinity="2"/>
                    <site rgba="0.5 0.0 0.0 1" size="0.001" pos="0 0 -0.16" name="finger_tip_120_site"/>
                </body>
            </body>
        </body>

        <!-- ================== ARM 3 (240 deg) ================== -->
        <body name="finger_upper_link_240" pos="-0.034641 -0.02 0.29"
              quat="-0.5 0 0 -0.866025">
            <inertial pos="0 0.06 0" quat="0.707107 0.707107 0 0"
                      mass="0.2" diaginertia="0.000353333 0.000353333 5.33333e-05"/>
            <joint name="finger_base_to_upper_joint_240" pos="0 0 0"
                   axis="0 1 0" limited="true" range="-1.5708 1.5708"/>

            <geom pos="0 -0.02695 0" type="mesh"
                  mesh="SIM__BL_Finger_Proximal"
                  rgba="0 0.5 0.5 1"
                  contype="1" conaffinity="2"/>

            <body name="finger_middle_link_240" pos="0 0 0">
                <inertial pos="0.028 0 -0.08" mass="0.2"
                          diaginertia="0.000353333 0.000353333 5.33333e-05"/>
                <joint name="finger_upper_to_middle_joint_240" pos="0 0 0"
                       axis="-1 0 0" limited="true"
                       range="-1.35263 4.49422"/>
                <geom pos="0.014 0 0" quat="0.707107 0.707107 0 0"
                      type="mesh" mesh="SIM__BL_Finger_Intermediate"
                      rgba="0 0.5 0.5 1"
                      contype="1" conaffinity="2"/>
                <body name="finger_lower_link_240" pos="0 0 -0.16">
                    <inertial pos="0 0 -0.126667" mass="0.03"
                              diaginertia="8.36667e-05 8.36667e-05 1e-06"/>
                    <joint name="finger_middle_to_lower_joint_240" pos="0 0 0"
                           axis="1 0 0" limited="true"
                           range="-3.00197 3.00197"/>
                    <geom name="finger_tip_240"
                          friction="0.9 0.005 0.0001"
                          pos="0.014 0 0" quat="0.707107 0.707107 0 0"
                          type="mesh" mesh="SIM__BL_FINGER_TIP_LINK"
                          rgba="0 0.5 0.5 1"
                          contype="1" conaffinity="2"/>
                    <site rgba="0.5 0.0 0.0 1" size="0.001" pos="0 0 -0.16" name="finger_tip_240_site"/>
                </body>
            </body>
        </body>

        <!-- =================== Adding the Cube =================== -->
        <body name="cube_link" pos="0 0 0">
            <!-- Free joint (6-DOF) -->
            <joint type="free"/>
            <!-- Inertial properties for the cube -->
            <inertial pos="0.0125 0.0125 0.0125" mass="0.03" 
                      diaginertia="0.0000052167 0.0000052167 0.0000052167"/>
            <!-- Geometry of the cube -->
            <geom name="cube_geom" type="box" size="0.0125 0.0125 0.0125" rgba="0.0 0.0 1.0 1.0" 
                  material="cube_material" 
                  friction="0.95 0.005 0.0001" margin="0"
                  contype="2" conaffinity="5"/> <!-- Enabled collisions with Robot and Table -->
        </body>
        <!-- =================== End of Cube Definition =================== -->
    </worldbody>

    <actuator>
        <position name="finger_base_to_upper_joint_0"   joint="finger_base_to_upper_joint_0"/>
        <position name="finger_upper_to_middle_joint_0" joint="finger_upper_to_middle_joint_0"/>
        <position name="finger_middle_to_lower_joint_0" joint="finger_middle_to_lower_joint_0"/>

        <position name="finger_base_to_upper_joint_120"   joint="finger_base_to_upper_joint_120"/>
        <position name="finger_upper_to_middle_joint_120" joint="finger_upper_to_middle_joint_120"/>
        <position name="finger_middle_to_lower_joint_120" joint="finger_middle_to_lower_joint_120"/>

        <position name="finger_base_to_upper_joint_240"   joint="finger_base_to_upper_joint_240"/>
        <position name="finger_upper_to_middle_joint_240" joint="finger_upper_to_middle_joint_240"/>
        <position name="finger_middle_to_lower_joint_240" joint="finger_middle_to_lower_joint_240"/>
    </actuator>

    <sensor>
        <!-- Positions of finger tips w.r.t the table -->
        <framepos name="tip_position_0"  objtype="site" objname="finger_tip_0_site"  reftype="geom" refname="table"/>
        <framepos name="tip_position_120" objtype="site" objname="finger_tip_120_site" reftype="geom" refname="table"/>
        <framepos name="tip_position_240" objtype="site" objname="finger_tip_240_site" reftype="geom" refname="table"/>
    </sensor>

    <keyframe>
        <key name="default"
             qpos="0.0 -0.6 -1.2  0.0 -0.6 -1.2  0.0 -0.6 -1.2 0.0 0.0 0.0 1.0 0.0 0.0 0.0"
             ctrl="0.0 -0.6 -1.2  0.0 -0.6 -1.2  0.0 -0.6 -1.2"/>
    </keyframe>

</mujoco>






